Workbook

Sheet 使用说明
A1: 《数据处理与分析》课程 · Day1–Day2 工作底稿 v0.5
A2: 海洋能源法领域地图 + 数据标注规范 | 85 份规范已录入
A4: ■ v0.5 相对 v0.3 的变更
A5: a. 主题标签「电力基础设施」更名「能源基础设施」:涵盖电网并网、海底电缆与油气管线、氢能储能——电只是转化方向之一
A6: b. 清单按 核心程度(高→低)→ 位阶(法律→政策文件)→ 施行日期(新→旧) 重排,序号重编
A7: c. 主/次标签与核心程度已经教师核对,紫色底纹取消;「关联规范」转为学生任务字段,已填20条为教师示范
A8: d. 学生人数按实际名单更新为52;总工作量1198人条,产能1300,余量102
A10: ■ v0.3 相对 v0.2 的变更
A11: A. 规范清单新增「区域」列(国家/11沿海省市):国家层与地方层共用一张表,机器比对央地规范只需筛选此列
A12: B. 字段定义新增镜像字段对:「央地权限配置」(国家层条目填)与「地方自主权类型」(地方层条目填),定义见受控词表
A13: C. 人均条目数上调为25;容量校验改按「产能 vs 总工作量(唯一条目+双人复核增量)」核算
A14: D. 地方层数据本期不采集,列入公开路线图;Schema 已就绪,未来零重构接入
... A36: ③ 据矩阵与容量校验结果调整认领方案 → ④ 确认【字段定义】v0.2 后,同步更新 Day3 学生模板

Sheet 规范清单
A1: Day1 · 海洋能源法规范清单(唯一数据源·国家层+地方层共用) v0.5
A2: 主/次标签与核心程度已经教师核对定稿。排序:核心程度(高→低)→位阶→施行日期(新→旧)。
A3: 核心程度≥4星(橙色行)由 2 名学生同时录入。「关联规范」为学生任务字段:标注本文件沿袭/取代/配套的另一份文件(单链),已填的20条为教师示范。
A4: 序号 | B4: 文件名称(全称) | C4: 文号 | D4: 位阶 | E4: 区域 | F4: 发布机关/牵头机关 | G4: 公布日期 | H4: 施行日期 | I4: 效力状态 | J4: 主题标签(主) | K4: 主题标签(次) | L4: 核心程度(1-5星) | M4: 关联规范 | N4: 预估可拆条目数 | O4: 难度等级 | P4: 已回数据库核实 | Q4: 线索来源 | R4: 备注
A5: 1 | B5: 中华人民共和国可再生能源法 | C5: 无文号 | D5: 法律 | E5: 国家 | F5: 全国人大及其常委会 | G5: 40173 | H5: 40269 | I5: 现行有效 | J5: 海洋可再生能源 | K5: 价格、财税与市场机制 | L5: 5 | N5: 18 | O5: 中 | P5: 是 | Q5: 国家法律法规数据库
A6: 2 | B6: 中华人民共和国海域使用管理法 | C6: 中华人民共和国主席令（第六十一号） | D6: 法律 | E6: 国家 | F6: 全国人大及其常委会 | G6: 37191 | H6: 37257 | I6: 现行有效 | J6: 海洋空间与用海管理 | K6: 价格、财税与市场机制 | L6: 5 | N6: 30 | O6: 中 | P6: 是 | Q6: 发布机关官网
A7: 3 | B7: 关于推动海洋能规模化利用的指导意见 | C7: 自然资发〔2025〕34号 | D7: 政策文件 | E7: 国家 | F7: 自然资源部 | G7: 45693 | H7: 45693 | I7: 现行有效 | J7: 海洋可再生能源 | K7: 规划与区划 | L7: 5 | N7: 25 | O7: 难 | P7: 是 | Q7: 发布机关官网
A8: 4 | B8: 自然资源部关于进一步加强海上风电项目用海管理的通知 | C8: 无文号 | D8: 政策文件 | E8: 国家 | F8: 自然资源部 | G8: 45656 | H8: 45656 | I8: 现行有效 | J8: 海洋空间与用海管理 | K8: 海洋可再生能源 | L8: 5 | N8: 30 | O8: 难 | P8: 是 | Q8: 发布机关官网
A9: 5 | B9: 中华人民共和国能源法 | C9: 中华人民共和国主席令第37号 | D9: 法律 | E9: 国家 | F9: 全国人大及其常委会 | G9: 45604 | H9: 45658 | I9: 现行有效 | J9: 海洋可再生能源 | K9: 能源基础设施 | L9: 4 | N9: 5 | O9: 易 | P9: 是 | Q9: 国家法律法规数据库
A10: 6 | B10: 中华人民共和国海岛保护法 | C10: 无文号 | D10: 法律 | E10: 国家 | F10: 全国人大及其常委会 | G10: 40173 | H10: 40238 | I10: 现行有效 | J10: 生态环境与海岛保护 | K10: 海洋空间与用海管理 | L10: 4 | N10: 40 | O10: 难 | P10: 是 | Q10: 国家法律法规数据库 | R10: 沿海省份地方条例，综合能源岛
A11: 7 | B11: 防治海洋工程建设项目污染损害海洋环境管理条例 | C11: 无文号 | D11: 行政法规 | E11: 国家 | F11: 国务院 | G11: 43543 | H11: 43543 | I11: 现行有效 | J11: 生态环境与海岛保护 | K11: 海洋可再生能源 | L11: 4 | N11: 40 | O11: 中 | P11: 是 | Q11: 发布机关官网
A12: 8 | B12: 中华人民共和国对外合作开采海洋石油资源条例 | C12: 中华人民共和国国务院令第607号 | D12: 行政法规 | E12: 国家 | F12: 国务院 | G12: 40826 | H12: 40848 | I12: 现行有效 | J12: 海洋油气与矿产资源 | K12: 海洋权益与涉外事务 | L12: 4 | N12: 30 | O12: 难 | P12: 是 | Q12: 国家法律法规数据库
A13: 9 | B13: 铺设海底电缆管道管理规定 | C13: 中华人民共和国国务院令第27号 | D13: 行政法规 | E13: 国家 | F13: 国务院 | G13: 32550 | H13: 32568 | I13: 现行有效 | J13: 能源基础设施 | K13: 海洋空间与用海管理 | L13: 4 | N13: 20 | O13: 难 | P13: 是 | Q13: 国家法律法规数据库
A14: 10 | B14: 自然资源部关于印发《临时用海管理办法》的通知 | C14: 自然资规〔2026〕3号 | D14: 规范性文件 | E14: 国家 | F14: 自然资源部 | G14: 46233 | H14: 46233 | I14: 现行有效 | J14: 海洋空间与用海管理 | L14: 4 | N14: 20 | O14: 中 | P14: 是 | Q14: 发布机关官网
A15: 11 | B15: 海上风电开发建设管理办法 | C15: 国能新能〔2016〕394号 | D15: 规范性文件 | E15: 国家 | F15: 国家能源局 | G15: 42733 | H15: 42733 | I15: 已废止 | J15: 海洋可再生能源 | K15: 海洋空间与用海管理 | L15: 4 | N15: 30 | O15: 易 | P15: 是 | Q15: 发布机关官网
A16: 12 | B16: 海洋可再生能源资金项目实施管理细则（暂行） | C16: 国海规范〔2016〕9号 | D16: 规范性文件 | E16: 国家 | F16: 国家海洋局(已并入自然资源部) | G16: 42726 | H16: 42726 | I16: 现行有效 | J16: 海洋可再生能源 | K16: 价格、财税与市场机制 | L16: 4 | N16: 15 | O16: 易 | P16: 是 | Q16: 发布机关官网
A17: 13 | B17: 国家发展改革委 国家能源局关于印发《新型电力系统建设“十五五”规划》的通知 | C17: 发改能源〔2026〕942号 | D17: 政策文件 | E17: 国家 | F17: 国家发展改革委 | G17: 46224 | H17: 46224 | I17: 现行有效 | J17: 规划与区划 | K17: 能源基础设施 | L17: 4 | N17: 4 | O17: 难 | P17: 是 | Q17: 发布机关官网
A18: 14 | B18: 关于印发《可再生能源发展“十五五”规划》的通知 | C18: 发改能源〔2026〕1067号 | D18: 政策文件 | E18: 国家 | F18: 国家发展改革委 | G18: 46209 | H18: 46209 | I18: 现行有效 | J18: 规划与区划 | K18: 海洋可再生能源 | L18: 4 | N18: 15 | O18: 难 | P18: 是 | Q18: 发布机关官网
A19: 15 | B19: 国家发展改革委 国家能源局关于印发《新型能源体系建设“十五五”规划》的通知 | C19: 发改能源〔2026〕884号 | D19: 政策文件 | E19: 国家 | F19: 国家发展改革委 | G19: 46186 | H19: 46186 | I19: 现行有效 | J19: 规划与区划 | K19: 能源基础设施 | L19: 4 | N19: 3 | O19: 难 | P19: 是 | Q19: 发布机关官网
A20: 16 | B20: 关于深化新能源上网电价市场化改革 促进新能源高质量发展的通知 | C20: 发改价格〔2025〕136号 | D20: 政策文件 | E20: 国家 | F20: 国家发展改革委 | G20: 45684 | H20: 45684 | I20: 现行有效 | J20: 价格、财税与市场机制 | K20: 海洋可再生能源 | L20: 4 | M20: 关于完善风电上网电价政策的通知 | N20: 8 | O20: 难 | P20: 是 | Q20: 发布机关官网
A21: 17 | B21: 自然资源部关于探索推进海域立体分层设权工作的通知 | C21: 自然资规〔2023〕8号 | D21: 政策文件 | E21: 国家 | F21: 自然资源部 | G21: 45243 | H21: 45243 | I21: 现行有效 | J21: 海洋空间与用海管理 | K21: 海洋可再生能源 | L21: 4 | N21: 20 | O21: 难 | P21: 是 | Q21: 发布机关官网
A22: 18 | B22: 关于完善风电上网电价政策的通知 | C22: 发改价格〔2019〕882号 | D22: 政策文件 | E22: 国家 | F22: 国家发展改革委 | G22: 43606 | H22: 43606 | I22: 现行有效 | J22: 价格、财税与市场机制 | K22: 海洋可再生能源 | L22: 4 | M22: 关于海上风电上网电价政策的通知 | N22: 4 | O22: 易 | P22: 是 | Q22: 发布机关官网
A23: 19 | B23: 关于海上风电上网电价政策的通知 | C23: 发改价格〔2014〕1216号 | D23: 政策文件 | E23: 国家 | F23: 国家发展改革委 | G23: 41795 | H23: 41795 | I23: 现行有效 | J23: 价格、财税与市场机制 | K23: 海洋可再生能源 | L23: 4 | N23: 3 | O23: 易 | P23: 是 | Q23: 发布机关官网
A24: 20 | B24: 中华人民共和国生态环境法典 | C24: 无文号 | D24: 法律 | E24: 国家 | F24: 全国人大及其常委会 | G24: 46093 | H24: 46249 | I24: 现行有效 | J24: 生态环境与海岛保护 | K24: 海洋空间与用海管理 | L24: 3 | N24: 20 | O24: 易 | P24: 是 | Q24: 国家法律法规数据库 | R24: 主要集中在海洋生态环境保护；沿海省份生态环境相关条例
A25: 21 | B25: 中华人民共和国矿产资源法 | C25: 无文号 | D25: 法律 | E25: 国家 | F25: 全国人大及其常委会 | G25: 45604 | H25: 45839 | I25: 现行有效 | J25: 海洋油气与矿产资源 | L25: 3 | N25: 40 | O25: 难 | P25: 是 | Q25: 国家法律法规数据库 | R25: 沿海省份地方条例
A26: 22 | B26: 中华人民共和国海上交通安全法 | C26: 无文号 | D26: 法律 | E26: 国家 | F26: 全国人大及其常委会 | G26: 44315 | H26: 44440 | I26: 现行有效 | J26: 海洋空间与用海管理 | K26: 能源基础设施 | L26: 3 | N26: 40 | O26: 中 | P26: 是 | Q26: 国家法律法规数据库 | R26: 沿海省份地方条例
A27: 23 | B27: 中华人民共和国电力法 | C27: 无文号 | D27: 法律 | E27: 国家 | F27: 全国人大及其常委会 | G27: 43463 | H27: 43463 | I27: 现行有效 | J27: 能源基础设施 | K27: 价格、财税与市场机制 | L27: 3 | N27: 40 | O27: 中 | P27: 是 | Q27: 国家法律法规数据库 | R27: 沿海省份地方条例
A28: 24 | B28: 中华人民共和国深海海底区域资源勘探开发法 | C28: 无文号 | D28: 法律 | E28: 国家 | F28: 全国人大及其常委会 | G28: 42426 | H28: 42491 | I28: 现行有效 | J28: 海洋油气与矿产资源 | K28: 海洋权益与涉外事务 | L28: 3 | N28: 30 | O28: 难 | P28: 是 | Q28: 国家法律法规数据库
A29: 25 | B29: 中华人民共和国专属经济区和大陆架法 | C29: 无文号 | D29: 法律 | E29: 国家 | F29: 全国人大及其常委会 | G29: 35972 | H29: 35972 | I29: 现行有效 | J29: 海洋权益与涉外事务 | K29: 海洋油气与矿产资源 | L29: 3 | N29: 15 | O29: 易 | P29: 是 | Q29: 国家法律法规数据库
A30: 26 | B30: 联合国海洋法公约 | C30: 中华人民共和国主席令（第六十九号） | D30: 法律 | E30: 国家 | F30: 全国人大及其常委会 | G30: 35200 | H30: 35200 | I30: 现行有效 | J30: 海洋权益与涉外事务 | K30: 海洋空间与用海管理 | L30: 3 | N30: 5 | O30: 中 | P30: 是 | Q30: 北大法宝 | R30: 全国人民代表大会常务委员会关于批准《联合国海洋法公约》的决定（1996）
A31: 27 | B31: 中华人民共和国领海及毗连区法 | C31: 无文号 | D31: 法律 | E31: 国家 | F31: 全国人大及其常委会 | G31: 33659 | H31: 33659 | I31: 现行有效 | J31: 海洋权益与涉外事务 | K31: 海洋空间与用海管理 | L31: 3 | N31: 20 | O31: 难 | P31: 是 | Q31: 国家法律法规数据库
A32: 28 | B32: 海洋观测预报管理条例 | C32: 中华人民共和国国务院令第615号 | D32: 行政法规 | E32: 国家 | F32: 国务院 | G32: 40969 | H32: 41061 | I32: 现行有效 | J32: 海洋观测与数据统计 | L32: 3 | N32: 7 | O32: 易 | P32: 是 | Q32: 发布机关官网
A33: 29 | B33: 保护海底电缆规定 | C33: 无文号 | D33: 行政法规 | E33: 国家 | F33: 国务院 | G33: 26814 | H33: 26814 | I33: 现行有效 | J33: 能源基础设施 | L33: 3 | M33: 铺设海底电缆管道管理规定 | N33: 5 | O33: 难 | P33: 是 | Q33: 国家法律法规数据库
A34: 30 | B34: 海洋观测站点管理办法 | C34: 中华人民共和国国土资源部令（第73号） | D34: 部门规章 | E34: 国家 | F34: 国土资源部（已并入自然资源部） | G34: 42893 | H34: 42893 | I34: 现行有效 | J34: 海洋观测与数据统计 | L34: 3 | M34: 海洋观测预报管理条例 | N34: 2 | O34: 易 | P34: 是 | Q34: 发布机关官网
A35: 31 | B35: 海洋观测资料管理办法 | C35: 中华人民共和国国土资源部令（第74号） | D35: 部门规章 | E35: 国家 | F35: 国土资源部（已并入自然资源部） | G35: 42893 | H35: 42893 | I35: 现行有效 | J35: 海洋观测与数据统计 | L35: 3 | M35: 海洋观测预报管理条例 | N35: 3 | O35: 易 | P35: 是 | Q35: 发布机关官网
A36: 32 | B36: 国务院关于印发全国海洋主体功能区规划的通知 | C36: 国发〔2015〕42号 | D36: 规范性文件 | E36: 国家 | F36: 国务院 | G36: 42236 | H36: 42217 | I36: 现行有效 | J36: 规划与区划 | K36: 海洋空间与用海管理 | L36: 3 | N36: 40 | O36: 难 | P36: 是 | Q36: 发布机关官网
A37: 33 | B37: 国务院关于印发《“十五五”碳达峰行动方案》的通知 | C37: 国发〔2026〕22号 | D37: 政策文件 | E37: 国家 | F37: 国务院 | G37: 46208 | H37: 46208 | I37: 现行有效 | J37: 规划与区划 | K37: 海洋可再生能源 | L37: 3 | N37: 2 | O37: 难 | P37: 是 | Q37: 发布机关官网
A38: 34 | B38: 国家能源局关于促进新能源集成融合发展的指导意见 | C38: 国能发新能〔2025〕93号 | D38: 政策文件 | E38: 国家 | F38: 国家能源局 | G38: 45961 | H38: 45961 | I38: 现行有效 | J38: 能源基础设施 | K38: 海洋可再生能源 | L38: 3 | N38: 5 | O38: 易 | P38: 是 | Q38: 发布机关官网
A39: 35 | B39: 关于促进新能源消纳和调控的指导意见 | C39: 发改能源〔2025〕1360号 | D39: 政策文件 | E39: 国家 | F39: 国家发展改革委 | G39: 45959 | H39: 45959 | I39: 现行有效 | J39: 能源基础设施 | K39: 海洋可再生能源 | L39: 3 | N39: 5 | O39: 难 | P39: 是 | Q39: 发布机关官网
A40: 36 | B40: 关于促进可再生能源绿色电力证书市场高质量发展的意见 | C40: 发改能源〔2025〕262号 | D40: 政策文件 | E40: 国家 | F40: 国家发展改革委 | G40: 45722 | H40: 45722 | I40: 现行有效 | J40: 价格、财税与市场机制 | K40: 海洋可再生能源 | L40: 3 | N40: 10 | O40: 中 | P40: 是 | Q40: 发布机关官网
...

Sheet 领域地图
A1: Day1 · 海洋能源法领域地图 v0.5(6位阶 × 9主题,自动汇总)
A2: 红色格=空白区,黄色格=薄弱区(≤2)。「地方立法」行现在整行为红是正常的——它就是你下一阶段的补充方向。
A4: 矩阵 A · 规范文件数(主标签+次标签)
A5: 位阶 \ 主题 | B5: 规划与区划 | C5: 海洋空间与用海管理 | D5: 海洋可再生能源 | E5: 海洋油气与矿产资源 | F5: 能源基础设施 | G5: 价格、财税与市场机制 | H5: 生态环境与海岛保护 | I5: 海洋权益与涉外事务 | J5: 海洋观测与数据统计 | K5: 合计
A6: 法律 | B6: =COUNTIFS(规范清单!$D$5:$D$204,$A6,规范清单!$J$5:$J$204,B$5)+COUNTIFS(规范清单!$D$5:$D$204,$A6,规范清单!$K$5:$K$204,B$5) | C6: =COUNTIFS(规范清单!$D$5:$D$204,$A6,规范清单!$J$5:$J$204,C$5)+COUNTIFS(规范清单!$D$5:$D$204,$A6,规范清单!$K$5:$K$204,C$5) | D6: =COUNTIFS(规范清单!$D$5:$D$204,$A6,规范清单!$J$5:$J$204,D$5)+COUNTIFS(规范清单!$D$5:$D$204,$A6,规范清单!$K$5:$K$204,D$5) | E6: =COUNTIFS(规范清单!$D$5:$D$204,$A6,规范清单!$J$5:$J$204,E$5)+COUNTIFS(规范清单!$D$5:$D$204,$A6,规范清单!$K$5:$K$204,E$5) | F6: =COUNTIFS(规范清单!$D$5:$D$204,$A6,规范清单!$J$5:$J$204,F$5)+COUNTIFS(规范清单!$D$5:$D$204,$A6,规范清单!$K$5:$K$204,F$5) | G6: =COUNTIFS(规范清单!$D$5:$D$204,$A6,规范清单!$J$5:$J$204,G$5)+COUNTIFS(规范清单!$D$5:$D$204,$A6,规范清单!$K$5:$K$204,G$5) | H6: =COUNTIFS(规范清单!$D$5:$D$204,$A6,规范清单!$J$5:$J$204,H$5)+COUNTIFS(规范清单!$D$5:$D$204,$A6,规范清单!$K$5:$K$204,H$5) | I6: =COUNTIFS(规范清单!$D$5:$D$204,$A6,规范清单!$J$5:$J$204,I$5)+COUNTIFS(规范清单!$D$5:$D$204,$A6,规范清单!$K$5:$K$204,I$5) | J6: =COUNTIFS(规范清单!$D$5:$D$204,$A6,规范清单!$J$5:$J$204,J$5)+COUNTIFS(规范清单!$D$5:$D$204,$A6,规范清单!$K$5:$K$204,J$5) | K6: =SUM(B6:J6)
A7: 行政法规 | B7: =COUNTIFS(规范清单!$D$5:$D$204,$A7,规范清单!$J$5:$J$204,B$5)+COUNTIFS(规范清单!$D$5:$D$204,$A7,规范清单!$K$5:$K$204,B$5) | C7: =COUNTIFS(规范清单!$D$5:$D$204,$A7,规范清单!$J$5:$J$204,C$5)+COUNTIFS(规范清单!$D$5:$D$204,$A7,规范清单!$K$5:$K$204,C$5) | D7: =COUNTIFS(规范清单!$D$5:$D$204,$A7,规范清单!$J$5:$J$204,D$5)+COUNTIFS(规范清单!$D$5:$D$204,$A7,规范清单!$K$5:$K$204,D$5) | E7: =COUNTIFS(规范清单!$D$5:$D$204,$A7,规范清单!$J$5:$J$204,E$5)+COUNTIFS(规范清单!$D$5:$D$204,$A7,规范清单!$K$5:$K$204,E$5) | F7: =COUNTIFS(规范清单!$D$5:$D$204,$A7,规范清单!$J$5:$J$204,F$5)+COUNTIFS(规范清单!$D$5:$D$204,$A7,规范清单!$K$5:$K$204,F$5) | G7: =COUNTIFS(规范清单!$D$5:$D$204,$A7,规范清单!$J$5:$J$204,G$5)+COUNTIFS(规范清单!$D$5:$D$204,$A7,规范清单!$K$5:$K$204,G$5) | H7: =COUNTIFS(规范清单!$D$5:$D$204,$A7,规范清单!$J$5:$J$204,H$5)+COUNTIFS(规范清单!$D$5:$D$204,$A7,规范清单!$K$5:$K$204,H$5) | I7: =COUNTIFS(规范清单!$D$5:$D$204,$A7,规范清单!$J$5:$J$204,I$5)+COUNTIFS(规范清单!$D$5:$D$204,$A7,规范清单!$K$5:$K$204,I$5) | J7: =COUNTIFS(规范清单!$D$5:$D$204,$A7,规范清单!$J$5:$J$204,J$5)+COUNTIFS(规范清单!$D$5:$D$204,$A7,规范清单!$K$5:$K$204,J$5) | K7: =SUM(B7:J7)
A8: 部门规章 | B8: =COUNTIFS(规范清单!$D$5:$D$204,$A8,规范清单!$J$5:$J$204,B$5)+COUNTIFS(规范清单!$D$5:$D$204,$A8,规范清单!$K$5:$K$204,B$5) | C8: =COUNTIFS(规范清单!$D$5:$D$204,$A8,规范清单!$J$5:$J$204,C$5)+COUNTIFS(规范清单!$D$5:$D$204,$A8,规范清单!$K$5:$K$204,C$5) | D8: =COUNTIFS(规范清单!$D$5:$D$204,$A8,规范清单!$J$5:$J$204,D$5)+COUNTIFS(规范清单!$D$5:$D$204,$A8,规范清单!$K$5:$K$204,D$5) | E8: =COUNTIFS(规范清单!$D$5:$D$204,$A8,规范清单!$J$5:$J$204,E$5)+COUNTIFS(规范清单!$D$5:$D$204,$A8,规范清单!$K$5:$K$204,E$5) | F8: =COUNTIFS(规范清单!$D$5:$D$204,$A8,规范清单!$J$5:$J$204,F$5)+COUNTIFS(规范清单!$D$5:$D$204,$A8,规范清单!$K$5:$K$204,F$5) | G8: =COUNTIFS(规范清单!$D$5:$D$204,$A8,规范清单!$J$5:$J$204,G$5)+COUNTIFS(规范清单!$D$5:$D$204,$A8,规范清单!$K$5:$K$204,G$5) | H8: =COUNTIFS(规范清单!$D$5:$D$204,$A8,规范清单!$J$5:$J$204,H$5)+COUNTIFS(规范清单!$D$5:$D$204,$A8,规范清单!$K$5:$K$204,H$5) | I8: =COUNTIFS(规范清单!$D$5:$D$204,$A8,规范清单!$J$5:$J$204,I$5)+COUNTIFS(规范清单!$D$5:$D$204,$A8,规范清单!$K$5:$K$204,I$5) | J8: =COUNTIFS(规范清单!$D$5:$D$204,$A8,规范清单!$J$5:$J$204,J$5)+COUNTIFS(规范清单!$D$5:$D$204,$A8,规范清单!$K$5:$K$204,J$5) | K8: =SUM(B8:J8)
A9: 地方立法 | B9: =COUNTIFS(规范清单!$D$5:$D$204,$A9,规范清单!$J$5:$J$204,B$5)+COUNTIFS(规范清单!$D$5:$D$204,$A9,规范清单!$K$5:$K$204,B$5) | C9: =COUNTIFS(规范清单!$D$5:$D$204,$A9,规范清单!$J$5:$J$204,C$5)+COUNTIFS(规范清单!$D$5:$D$204,$A9,规范清单!$K$5:$K$204,C$5) | D9: =COUNTIFS(规范清单!$D$5:$D$204,$A9,规范清单!$J$5:$J$204,D$5)+COUNTIFS(规范清单!$D$5:$D$204,$A9,规范清单!$K$5:$K$204,D$5) | E9: =COUNTIFS(规范清单!$D$5:$D$204,$A9,规范清单!$J$5:$J$204,E$5)+COUNTIFS(规范清单!$D$5:$D$204,$A9,规范清单!$K$5:$K$204,E$5) | F9: =COUNTIFS(规范清单!$D$5:$D$204,$A9,规范清单!$J$5:$J$204,F$5)+COUNTIFS(规范清单!$D$5:$D$204,$A9,规范清单!$K$5:$K$204,F$5) | G9: =COUNTIFS(规范清单!$D$5:$D$204,$A9,规范清单!$J$5:$J$204,G$5)+COUNTIFS(规范清单!$D$5:$D$204,$A9,规范清单!$K$5:$K$204,G$5) | H9: =COUNTIFS(规范清单!$D$5:$D$204,$A9,规范清单!$J$5:$J$204,H$5)+COUNTIFS(规范清单!$D$5:$D$204,$A9,规范清单!$K$5:$K$204,H$5) | I9: =COUNTIFS(规范清单!$D$5:$D$204,$A9,规范清单!$J$5:$J$204,I$5)+COUNTIFS(规范清单!$D$5:$D$204,$A9,规范清单!$K$5:$K$204,I$5) | J9: =COUNTIFS(规范清单!$D$5:$D$204,$A9,规范清单!$J$5:$J$204,J$5)+COUNTIFS(规范清单!$D$5:$D$204,$A9,规范清单!$K$5:$K$204,J$5) | K9: =SUM(B9:J9)
A10: 规范性文件 | B10: =COUNTIFS(规范清单!$D$5:$D$204,$A10,规范清单!$J$5:$J$204,B$5)+COUNTIFS(规范清单!$D$5:$D$204,$A10,规范清单!$K$5:$K$204,B$5) | C10: =COUNTIFS(规范清单!$D$5:$D$204,$A10,规范清单!$J$5:$J$204,C$5)+COUNTIFS(规范清单!$D$5:$D$204,$A10,规范清单!$K$5:$K$204,C$5) | D10: =COUNTIFS(规范清单!$D$5:$D$204,$A10,规范清单!$J$5:$J$204,D$5)+COUNTIFS(规范清单!$D$5:$D$204,$A10,规范清单!$K$5:$K$204,D$5) | E10: =COUNTIFS(规范清单!$D$5:$D$204,$A10,规范清单!$J$5:$J$204,E$5)+COUNTIFS(规范清单!$D$5:$D$204,$A10,规范清单!$K$5:$K$204,E$5) | F10: =COUNTIFS(规范清单!$D$5:$D$204,$A10,规范清单!$J$5:$J$204,F$5)+COUNTIFS(规范清单!$D$5:$D$204,$A10,规范清单!$K$5:$K$204,F$5) | G10: =COUNTIFS(规范清单!$D$5:$D$204,$A10,规范清单!$J$5:$J$204,G$5)+COUNTIFS(规范清单!$D$5:$D$204,$A10,规范清单!$K$5:$K$204,G$5) | H10: =COUNTIFS(规范清单!$D$5:$D$204,$A10,规范清单!$J$5:$J$204,H$5)+COUNTIFS(规范清单!$D$5:$D$204,$A10,规范清单!$K$5:$K$204,H$5) | I10: =COUNTIFS(规范清单!$D$5:$D$204,$A10,规范清单!$J$5:$J$204,I$5)+COUNTIFS(规范清单!$D$5:$D$204,$A10,规范清单!$K$5:$K$204,I$5) | J10: =COUNTIFS(规范清单!$D$5:$D$204,$A10,规范清单!$J$5:$J$204,J$5)+COUNTIFS(规范清单!$D$5:$D$204,$A10,规范清单!$K$5:$K$204,J$5) | K10: =SUM(B10:J10)
A11: 政策文件 | B11: =COUNTIFS(规范清单!$D$5:$D$204,$A11,规范清单!$J$5:$J$204,B$5)+COUNTIFS(规范清单!$D$5:$D$204,$A11,规范清单!$K$5:$K$204,B$5) | C11: =COUNTIFS(规范清单!$D$5:$D$204,$A11,规范清单!$J$5:$J$204,C$5)+COUNTIFS(规范清单!$D$5:$D$204,$A11,规范清单!$K$5:$K$204,C$5) | D11: =COUNTIFS(规范清单!$D$5:$D$204,$A11,规范清单!$J$5:$J$204,D$5)+COUNTIFS(规范清单!$D$5:$D$204,$A11,规范清单!$K$5:$K$204,D$5) | E11: =COUNTIFS(规范清单!$D$5:$D$204,$A11,规范清单!$J$5:$J$204,E$5)+COUNTIFS(规范清单!$D$5:$D$204,$A11,规范清单!$K$5:$K$204,E$5) | F11: =COUNTIFS(规范清单!$D$5:$D$204,$A11,规范清单!$J$5:$J$204,F$5)+COUNTIFS(规范清单!$D$5:$D$204,$A11,规范清单!$K$5:$K$204,F$5) | G11: =COUNTIFS(规范清单!$D$5:$D$204,$A11,规范清单!$J$5:$J$204,G$5)+COUNTIFS(规范清单!$D$5:$D$204,$A11,规范清单!$K$5:$K$204,G$5) | H11: =COUNTIFS(规范清单!$D$5:$D$204,$A11,规范清单!$J$5:$J$204,H$5)+COUNTIFS(规范清单!$D$5:$D$204,$A11,规范清单!$K$5:$K$204,H$5) | I11: =COUNTIFS(规范清单!$D$5:$D$204,$A11,规范清单!$J$5:$J$204,I$5)+COUNTIFS(规范清单!$D$5:$D$204,$A11,规范清单!$K$5:$K$204,I$5) | J11: =COUNTIFS(规范清单!$D$5:$D$204,$A11,规范清单!$J$5:$J$204,J$5)+COUNTIFS(规范清单!$D$5:$D$204,$A11,规范清单!$K$5:$K$204,J$5) | K11: =SUM(B11:J11)
A12: 合计 | B12: =SUM(B6:B11) | C12: =SUM(C6:C11) | D12: =SUM(D6:D11) | E12: =SUM(E6:E11) | F12: =SUM(F6:F11) | G12: =SUM(G6:G11) | H12: =SUM(H6:H11) | I12: =SUM(I6:I11) | ... K12: =SUM(K6:K11)
A15: 矩阵 B · 预估可拆条目数(按主标签统计)
A16: 位阶 \ 主题 | B16: 规划与区划 | C16: 海洋空间与用海管理 | D16: 海洋可再生能源 | E16: 海洋油气与矿产资源 | F16: 能源基础设施 | G16: 价格、财税与市场机制 | H16: 生态环境与海岛保护 | I16: 海洋权益与涉外事务 | J16: 海洋观测与数据统计 | K16: 合计
A17: 法律 | B17: =SUMIFS(规范清单!$N$5:$N$204,规范清单!$D$5:$D$204,$A17,规范清单!$J$5:$J$204,B$16) | C17: =SUMIFS(规范清单!$N$5:$N$204,规范清单!$D$5:$D$204,$A17,规范清单!$J$5:$J$204,C$16) | D17: =SUMIFS(规范清单!$N$5:$N$204,规范清单!$D$5:$D$204,$A17,规范清单!$J$5:$J$204,D$16) | E17: =SUMIFS(规范清单!$N$5:$N$204,规范清单!$D$5:$D$204,$A17,规范清单!$J$5:$J$204,E$16) | F17: =SUMIFS(规范清单!$N$5:$N$204,规范清单!$D$5:$D$204,$A17,规范清单!$J$5:$J$204,F$16) | G17: =SUMIFS(规范清单!$N$5:$N$204,规范清单!$D$5:$D$204,$A17,规范清单!$J$5:$J$204,G$16) | H17: =SUMIFS(规范清单!$N$5:$N$204,规范清单!$D$5:$D$204,$A17,规范清单!$J$5:$J$204,H$16) | I17: =SUMIFS(规范清单!$N$5:$N$204,规范清单!$D$5:$D$204,$A17,规范清单!$J$5:$J$204,I$16) | J17: =SUMIFS(规范清单!$N$5:$N$204,规范清单!$D$5:$D$204,$A17,规范清单!$J$5:$J$204,J$16) | K17: =SUM(B17:J17)
A18: 行政法规 | B18: =SUMIFS(规范清单!$N$5:$N$204,规范清单!$D$5:$D$204,$A18,规范清单!$J$5:$J$204,B$16) | C18: =SUMIFS(规范清单!$N$5:$N$204,规范清单!$D$5:$D$204,$A18,规范清单!$J$5:$J$204,C$16) | D18: =SUMIFS(规范清单!$N$5:$N$204,规范清单!$D$5:$D$204,$A18,规范清单!$J$5:$J$204,D$16) | E18: =SUMIFS(规范清单!$N$5:$N$204,规范清单!$D$5:$D$204,$A18,规范清单!$J$5:$J$204,E$16) | F18: =SUMIFS(规范清单!$N$5:$N$204,规范清单!$D$5:$D$204,$A18,规范清单!$J$5:$J$204,F$16) | G18: =SUMIFS(规范清单!$N$5:$N$204,规范清单!$D$5:$D$204,$A18,规范清单!$J$5:$J$204,G$16) | H18: =SUMIFS(规范清单!$N$5:$N$204,规范清单!$D$5:$D$204,$A18,规范清单!$J$5:$J$204,H$16) | I18: =SUMIFS(规范清单!$N$5:$N$204,规范清单!$D$5:$D$204,$A18,规范清单!$J$5:$J$204,I$16) | J18: =SUMIFS(规范清单!$N$5:$N$204,规范清单!$D$5:$D$204,$A18,规范清单!$J$5:$J$204,J$16) | K18: =SUM(B18:J18)
A19: 部门规章 | B19: =SUMIFS(规范清单!$N$5:$N$204,规范清单!$D$5:$D$204,$A19,规范清单!$J$5:$J$204,B$16) | C19: =SUMIFS(规范清单!$N$5:$N$204,规范清单!$D$5:$D$204,$A19,规范清单!$J$5:$J$204,C$16) | D19: =SUMIFS(规范清单!$N$5:$N$204,规范清单!$D$5:$D$204,$A19,规范清单!$J$5:$J$204,D$16) | E19: =SUMIFS(规范清单!$N$5:$N$204,规范清单!$D$5:$D$204,$A19,规范清单!$J$5:$J$204,E$16) | F19: =SUMIFS(规范清单!$N$5:$N$204,规范清单!$D$5:$D$204,$A19,规范清单!$J$5:$J$204,F$16) | G19: =SUMIFS(规范清单!$N$5:$N$204,规范清单!$D$5:$D$204,$A19,规范清单!$J$5:$J$204,G$16) | H19: =SUMIFS(规范清单!$N$5:$N$204,规范清单!$D$5:$D$204,$A19,规范清单!$J$5:$J$204,H$16) | I19: =SUMIFS(规范清单!$N$5:$N$204,规范清单!$D$5:$D$204,$A19,规范清单!$J$5:$J$204,I$16) | J19: =SUMIFS(规范清单!$N$5:$N$204,规范清单!$D$5:$D$204,$A19,规范清单!$J$5:$J$204,J$16) | K19: =SUM(B19:J19)
A20: 地方立法 | B20: =SUMIFS(规范清单!$N$5:$N$204,规范清单!$D$5:$D$204,$A20,规范清单!$J$5:$J$204,B$16) | C20: =SUMIFS(规范清单!$N$5:$N$204,规范清单!$D$5:$D$204,$A20,规范清单!$J$5:$J$204,C$16) | D20: =SUMIFS(规范清单!$N$5:$N$204,规范清单!$D$5:$D$204,$A20,规范清单!$J$5:$J$204,D$16) | E20: =SUMIFS(规范清单!$N$5:$N$204,规范清单!$D$5:$D$204,$A20,规范清单!$J$5:$J$204,E$16) | F20: =SUMIFS(规范清单!$N$5:$N$204,规范清单!$D$5:$D$204,$A20,规范清单!$J$5:$J$204,F$16) | G20: =SUMIFS(规范清单!$N$5:$N$204,规范清单!$D$5:$D$204,$A20,规范清单!$J$5:$J$204,G$16) | H20: =SUMIFS(规范清单!$N$5:$N$204,规范清单!$D$5:$D$204,$A20,规范清单!$J$5:$J$204,H$16) | I20: =SUMIFS(规范清单!$N$5:$N$204,规范清单!$D$5:$D$204,$A20,规范清单!$J$5:$J$204,I$16) | J20: =SUMIFS(规范清单!$N$5:$N$204,规范清单!$D$5:$D$204,$A20,规范清单!$J$5:$J$204,J$16) | K20: =SUM(B20:J20)
A21: 规范性文件 | B21: =SUMIFS(规范清单!$N$5:$N$204,规范清单!$D$5:$D$204,$A21,规范清单!$J$5:$J$204,B$16) | C21: =SUMIFS(规范清单!$N$5:$N$204,规范清单!$D$5:$D$204,$A21,规范清单!$J$5:$J$204,C$16) | D21: =SUMIFS(规范清单!$N$5:$N$204,规范清单!$D$5:$D$204,$A21,规范清单!$J$5:$J$204,D$16) | E21: =SUMIFS(规范清单!$N$5:$N$204,规范清单!$D$5:$D$204,$A21,规范清单!$J$5:$J$204,E$16) | F21: =SUMIFS(规范清单!$N$5:$N$204,规范清单!$D$5:$D$204,$A21,规范清单!$J$5:$J$204,F$16) | G21: =SUMIFS(规范清单!$N$5:$N$204,规范清单!$D$5:$D$204,$A21,规范清单!$J$5:$J$204,G$16) | H21: =SUMIFS(规范清单!$N$5:$N$204,规范清单!$D$5:$D$204,$A21,规范清单!$J$5:$J$204,H$16) | I21: =SUMIFS(规范清单!$N$5:$N$204,规范清单!$D$5:$D$204,$A21,规范清单!$J$5:$J$204,I$16) | J21: =SUMIFS(规范清单!$N$5:$N$204,规范清单!$D$5:$D$204,$A21,规范清单!$J$5:$J$204,J$16) | K21: =SUM(B21:J21)
A22: 政策文件 | B22: =SUMIFS(规范清单!$N$5:$N$204,规范清单!$D$5:$D$204,$A22,规范清单!$J$5:$J$204,B$16) | C22: =SUMIFS(规范清单!$N$5:$N$204,规范清单!$D$5:$D$204,$A22,规范清单!$J$5:$J$204,C$16) | D22: =SUMIFS(规范清单!$N$5:$N$204,规范清单!$D$5:$D$204,$A22,规范清单!$J$5:$J$204,D$16) | E22: =SUMIFS(规范清单!$N$5:$N$204,规范清单!$D$5:$D$204,$A22,规范清单!$J$5:$J$204,E$16) | F22: =SUMIFS(规范清单!$N$5:$N$204,规范清单!$D$5:$D$204,$A22,规范清单!$J$5:$J$204,F$16) | G22: =SUMIFS(规范清单!$N$5:$N$204,规范清单!$D$5:$D$204,$A22,规范清单!$J$5:$J$204,G$16) | H22: =SUMIFS(规范清单!$N$5:$N$204,规范清单!$D$5:$D$204,$A22,规范清单!$J$5:$J$204,H$16) | I22: =SUMIFS(规范清单!$N$5:$N$204,规范清单!$D$5:$D$204,$A22,规范清单!$J$5:$J$204,I$16) | J22: =SUMIFS(规范清单!$N$5:$N$204,规范清单!$D$5:$D$204,$A22,规范清单!$J$5:$J$204,J$16) | K22: =SUM(B22:J22)
A23: 合计 | B23: =SUM(B17:B22) | C23: =SUM(C17:C22) | D23: =SUM(D17:D22) | E23: =SUM(E17:E22) | F23: =SUM(F17:F22) | G23: =SUM(G17:G22) | H23: =SUM(H17:H22) | I23: =SUM(I17:I22) | ... K23: =SUM(K17:K22)
A26: 容量核算 v0.3 · 产能 vs 总工作量(含双人复核)
A27: 学生人数(国家层班级) | B27: 52
A28: 人均条目数 | B28: 25
A29: 班级总产能(人条) | B29: =B27*B28
A30: 地图预估唯一条目 | B30: =K23
A31: ≥4星规范文件数 | B31: =COUNTIF(规范清单!$L$5:$L$204,">=4")
A32: 双人复核增量(≥4星条目,第二人重做) | B32: =SUMIFS(规范清单!$N$5:$N$204,规范清单!$L$5:$L$204,">=4")
A33: 总工作量(唯一条目+复核增量) | B33: =B30+B32
A34: 产能余量 | B34: =B29-B33
A35: 结论 | B35: =IF(B29=0,"请先填写人数与人均条目",IF(B34>=0,"产能可覆盖国家层。余量为 "&B34&" 人条:余量很小时,废稿与返工主要由v1→v2修订轮吸收","缺口 "&ABS(B34)&" 人条:①下调4星名单 ②人均再上调 ③削减低星文件条目"))
A37: v0.3 起不再使用盲目冗余系数:认领制避免重复选题,双人复核承担质量冗余,二者已替代其功能。地方层(第二班级)开启后,复制本块并按区域筛选另行核算。
A39: 提示:双人录入不是简单加倍——两人独立完成后比对差异,差异本身就是课堂讨论素材,也是数据质量的天然检验。

Sheet 字段定义
A1: Day2 · 数据标注规范 v0.5 · 字段定义
A2: v0.3 变更:新增制定区域、央地权限配置(国家层填)、地方自主权类型(地方层填)。v0.2 变更:文号(法律可不填)、位阶(地方立法)、条文定位(允许第X段)、行为模式类型(增指导性)、主题标签(九类)。改动须升版本并记入【修订日志】。
A4: 序 | B4: 字段名 | C4: 字段ID(英文) | D4: 必填 | E4: 数据类型 | F4: 取值约束 | G4: 校验规则(供Day4脚本) | H4: 填写说明 | I4: 常见错误
A5: 1 | B5: 条目ID | C5: entry_id | D5: 是 | E5: 文本 | F5: S##-### | G5: 正则 ^S\d{2}-\d{3}$;全库唯一 | H5: 学生编号+三位序号,如 S07-013。由录入人自行编号,组内不得重复。 | I5: 用了姓名拼音;序号不补零
A6: 2 | B6: 文件名称 | C6: doc_title | D6: 是 | E6: 文本 | F6: 规范全称 | G6: 非空;不得用简称 | H6: 必须写全称。机器无法把简称与全称对齐。 | I6: 写简称;书名号全半角混用
A7: 3 | B7: 文号 | C7: doc_number | D7: 条件必填 | E7: 文本 | F7: 〔〕六角括号;法律可不填 | G7: 法律位阶:可空或填「无文号」;其余位阶:非空且含年份 | H7: 法律用主席令号或不填;确无文号的文件明确写「无文号」,以区别于漏填。注意是〔〕不是[]。 | I7: 误用方括号;漏年份;漏填与无文号不分
A8: 4 | B8: 位阶 | C8: hierarchy | D8: 是 | E8: 枚举 | F8: 法律/行政法规/部门规章/地方立法/规范性文件/政策文件 | G8: 必须∈六个枚举值 | H8: 「地方立法」涵盖地方性法规与地方政府规章,录入时在备注注明具体类型。 | I8: 把「办法」一律当规章;地方立法内部类型不注明
A9: 5 | B9: 制定区域 | C9: region | D9: 是 | E9: 枚举 | F9: 国家/11沿海省市 | G9: 必须∈十二个枚举值;区域与位阶匹配(地方立法不得填「国家」,法律/行政法规/部门规章不得填省市) | H9: 国家层条目填「国家」。地方层条目填省市名——这是央地比对的筛选键。 | I9: 地方规范误填国家;区域与位阶矛盾
A10: 5 | B10: 发布机关/牵头机关 | C10: issuer | D10: 是 | E10: 枚举+自由 | F10: 见受控词表 | G10: 须与位阶匹配(如部门规章不得由省政府发布) | H10: 联合发文取牵头机关,其余机关写入备注。机构改革后的名称变化要注明。 | I10: 用改革前的旧机关名而不加注;联合发文只记一个机关且不注其余
A11: 6 | B11: 公布日期 | C11: promulgate_date | D11: 是 | E11: 日期 | F11: YYYY-MM-DD | G11: 日期格式;不晚于施行日期 | H11: 公布与施行常常不是同一天,分开记录。 | I11: 两个日期填成同一天
A12: 7 | B12: 施行日期 | C12: effective_date | D12: 是 | E12: 日期 | F12: YYYY-MM-DD | G12: 日期格式 | H12: 以文件本身载明的施行日为准。 | I12: 填成检索当天的日期
A13: 8 | B13: 效力状态 | C13: status | D13: 是 | E13: 枚举 | F13: 现行有效/已修订/已废止/尚未生效 | G13: 必须∈枚举;与失效日期逻辑一致 | H13: 「已修订」指本文本已被新版取代,必须在备注注明现行版本。 | I13: 把修订过的法律标为现行有效而不注版本
A14: 9 | B14: 失效或修订日期 | C14: end_date | D14: 条件必填 | E14: 日期 | F14: YYYY-MM-DD | G14: 状态非「现行有效」时必填;须晚于施行日期 | H14: 这是数据库最容易自相矛盾的地方,务必与状态列对照检查。 | I14: 状态填已废止但日期留空
A15: 10 | B15: 主题标签(主) | C15: topic_main | D15: 是 | E15: 枚举 | F15: 九类,见受控词表标签定义表 | G15: 必须∈九个枚举值 | H15: 对应领域地图九类。一条数据只能有一个主标签。规范级标签是粗定位,条目级标签才是检索主力:同一部法律的不同条文可以打不同标签。 | I15: 一条数据勾了多个主题;整部法的条目全打同一标签而不看条文内容
A16: 11 | B16: 主题标签(次) | C16: topic_sub | D16: 否 | E16: 枚举 | F16: 九类,见受控词表标签定义表 | G16: ∈枚举或空;不得与主标签相同 | H16: 跨主题条款用次标签补充,便于交叉检索。 | I16: 次标签与主标签重复
... A29: 24 | B29: 版本 | C29: version | D29: 是 | E29: 枚举 | F29: v1/v2/定稿 | G29: 必须∈枚举 | H29: v1 为首轮提交,v2 为校验反馈后的修订稿。 | I29: 修订后不改版本号
A30: 25 | B30: 录入日期 | C30: entry_date | D30: 是 | E30: 日期 | F30: YYYY-MM-DD | G30: 日期格式
A31: 26 | B31: 备注 | C31: remark | D31: 否 | E31: 文本 | H31: 版本变化、机构沿革、地方立法具体类型、存疑之处写在这里。存疑不是扣分项,隐瞒才是。
A33: 绿色高亮的五要素字段是本课灵魂。v0.2 的重要深化:「指导性」类型让学生看到经济公法的规范特征——除确定性规则外,大量框架性规则只指明方向、无直接执行力,其功能恰恰在于为经济活动留下创造空间。建议在讲五要素的那次课上,用一条电价政策与一条海域法条文对比讲解。v0.3 新增的镜像字段对(央地权限配置↔地方自主权类型)是本库独有的分析仪器:国家层记录中央「授予了什么」,地方层记录地方「行使了什么」,期末交叉即得央地权限配置矩阵——错配本身就是发现。

Sheet 受控词表
A1: 受控词表 v0.5(枚举值唯一来源)
A2: 位阶 | B2: 主题标签 | C2: 发布机关/牵头机关 | D2: 行为模式类型 | E2: 效力状态 | F2: 难度等级 | G2: 是/否 | H2: 线索/核实来源 | I2: 版本 | J2: 核心程度 | K2: 区域 | L2: 央地权限配置 | M2: 地方自主权类型
A3: 法律 | B3: 规划与区划 | C3: 全国人大及其常委会 | D3: 义务性 | E3: 现行有效 | F3: 易 | G3: 是 | H3: 北大法宝 | I3: v1 | J3: 1 | K3: 国家 | L3: 统一执行 | M3: 执行性
A4: 行政法规 | B4: 海洋空间与用海管理 | C4: 国务院 | D4: 授权性 | E4: 已修订 | F4: 中 | G4: 否 | H4: 威科先行 | I4: v2 | J4: 2 | K4: 辽宁 | L4: 授权细化 | M4: 细化性
A5: 部门规章 | B5: 海洋可再生能源 | C5: 自然资源部 | D5: 禁止性 | E5: 已废止 | F5: 难 | H5: 国家法律法规数据库 | I5: 定稿 | J5: 3 | K5: 河北 | L5: 因地制宜 | M5: 创设性
A6: 地方立法 | B6: 海洋油气与矿产资源 | C6: 国家能源局 | D6: 定义性 | E6: 尚未生效 | H6: 国家行政法规数据库 | J6: 4 | K6: 天津 | L6: 未作规定 | M6: 可协商性
A7: 规范性文件 | B7: 能源基础设施 | C7: 生态环境部 | D7: 程序性 | H7: 发布机关官网 | J7: 5 | K7: 山东 | L7: 中央专属 | M7: 无权限(存疑)
A8: 政策文件 | B8: 价格、财税与市场机制 | C8: 国家发展改革委 | D8: 指导性 | H8: 其他 | K8: 江苏
B9: 生态环境与海岛保护 | C9: 财政部 | D9: 惩罚性 | K9: 浙江
B10: 海洋权益与涉外事务 | C10: 交通运输部 | K10: 上海
B11: 海洋观测与数据统计 | C11: 农业农村部 | K11: 福建
C12: 国家海洋局(已并入自然资源部) | K12: 广东
C13: 国土资源部（已并入自然资源部） | K13: 广西
C14: 省级人大及其常委会 | K14: 海南
C15: 省级人民政府
C16: 省级主管部门
C17: 其他
A21: 主题标签定义表(九类)
A22: 标签 | B22: 覆盖范围 | C22: 典型文件(来自本清单)
A23: 规划与区划 | B23: 发展规划、专项规划、功能区划、区划批复及规划法制 | C23: 国家发展规划法;全国海洋主体功能区规划;各省海洋功能区划批复;可再生能源发展“十五五”规划
A24: 海洋空间与用海管理 | B24: 海域使用权取得、审批、论证、立体分层设权、临时用海、用海要素保障 | C24: 海域使用管理法;临时用海管理办法;海域立体分层设权通知
A25: 海洋可再生能源 | B25: 海上风电、海洋能(潮流能、波浪能等)的开发利用与产业促进 | C25: 可再生能源法;海上风电开发建设管理办法;推动海洋能规模化利用的指导意见
A26: 海洋油气与矿产资源 | B26: 海洋石油天然气、海砂、深海海底矿产的勘探开发 | C26: 对外合作开采海洋石油资源条例;深海海底区域资源勘探开发法;海砂两权合一通知
A27: 能源基础设施 | B27: 电网与并网消纳、海底电缆与油气管线、氢能与储能等输送转化设施——电只是海洋能源的转化方向之一,管线承载油气、氢、淡化水等多种形态 | C27: 电力法;铺设海底电缆管道管理规定;新能源消纳和调控指导意见
A28: 价格、财税与市场机制 | B28: 上网电价、海域使用金、财税措施、绿证等市场工具 | C28: 海上风电上网电价通知;海域使用金征收标准;绿证市场高质量发展意见
A29: 生态环境与海岛保护 | B29: 海洋生态环境保护、污染防治、海岛保护 | C29: 生态环境法典;防治海洋工程污染条例;海岛保护法
A30: 海洋权益与涉外事务 | B30: 领海、专属经济区、大陆架、涉外合作与主权权益 | C30: 联合国海洋法公约;专属经济区和大陆架法;涉外海洋科学研究管理规定
A31: 海洋观测与数据统计 | B31: 海洋观测预报、观测站点与资料、海洋经济统计核算 | C31: 海洋观测预报管理条例;海洋观测资料管理办法;海洋经济统计调查制度
A33: 边界规则:①标签按对象划分,规范功能由条目级「行为模式类型」承担 ②综合性法律(如能源法)的文件级标签只做粗定位,真正的检索靠条目级标签 ③安全类规范暂不独立设标签(现仅海上交通安全法1部,归入海洋空间与用海管理),地方立法补充后若安全类规范增多,再增设「安全与应急」。
A35: 镜像字段对定义表(v0.3):央地权限配置(国家层)↔ 地方自主权类型(地方层)
A36: 国家层取值 | B36: 含义 | C36: 地方层取值 | D36: 含义
A37: 统一执行 | B37: 中央:全国一体适用,地方仅负执行之责,无裁量空间 | C37: 执行性 | D37: 地方:重述或直接执行上位规范,无实质新增内容
A38: 授权细化 | B38: 中央:明确授权地方作出具体规定 | C38: 细化性 | D38: 地方:在上位授权或框架内具体化标准、程序、幅度
A39: 因地制宜 | B39: 中央:允许地方选择幅度、方式、时点,含试点授权 | C39: 创设性 | D39: 地方:对上位法未规定事项先行创制
A40: 未作规定 | B40: 中央:对地方权限保持沉默 | C40: 可协商性 | D40: 地方:基于央地协商机制形成(试点批复、部省协议等)
A41: 中央专属 | B41: 中央:事项明示或依性质专属中央 | C41: 无权限(存疑) | D41: 地方:疑属中央专属或缺上位依据——标记疑点,不下违法结论
A43: 注意:两列取值并非一一对应关系,同行仅为排版。分析时做的是交叉矩阵:例如中央「授权细化」×地方「创设性」=疑似越界;中央「未作规定」×地方「创设性」=先行先试空间。期末由两班数据交叉计算。

Sheet 示例数据
A1: Day2 · 示范条目 v0.5(满分 / 错误 / 边界 / 指导性 / 地方层示意)
A2: 新增第4行(蓝色):政策文件+指导性+段落定位的示范。条文内容须回权威数据库核实后再用于教学。
A4: 条目ID | B4: 文件名称 | C4: 文号 | D4: 位阶 | E4: 制定区域 | F4: 发布机关/牵头机关 | G4: 公布日期 | H4: 施行日期 | I4: 效力状态 | J4: 失效或修订日期 | K4: 主题标签(主) | L4: 主题标签(次) | M4: 条文定位 | N4: 规范主体 | O4: 适用条件 | P4: 行为模式类型 | Q4: 行为模式内容 | R4: 法律后果 | S4: 原文摘录 | T4: 关联条目 | U4: 央地权限配置 | V4: 地方自主权类型 | W4: 核实来源 | X4: 录入人 | Y4: 版本 | Z4: 录入日期 | AA4: 备注
A5: S07-001 | B5: 中华人民共和国海域使用管理法 | C5: 主席令第六十一号 | D5: 法律 | E5: 国家 | F5: 全国人大及其常委会 | G5: 2001-10-27 | H5: 2002-01-01 | I5: 现行有效 | K5: 海洋空间与用海管理 | M5: 第十六条第一款 | N5: 单位和个人(海域使用申请人) | O5: 拟使用未确定使用权的海域 | P5: 程序性 | Q5: 向县级以上人民政府海洋行政主管部门提出用海申请,并提交规定的申请材料 | R5: 本条未设 | S5: 【核实后填入不超过200字的原文】 | T5: S07-004 | U5: 统一执行 | W5: 国家法律法规数据库 | X5: 2023001 张三 | Y5: v1 | Z5: 2026-08-20 | AA5: 满分示范:审批程序全国一体,县级以上地方机关是执行主体而非规定权主体,故央地权限配置=统一执行
A6: s7-2 | B6: 《海域法》 | D6: 法律 | E6: 国家 | F6: 国家海洋局 | G6: 2002 | H6: 2002 | I6: 现行有效 | K6: 海洋空间与用海管理、规划与区划 | L6: 海洋空间与用海管理 | M6: 第十六条 | N6: 国家 | O6: / | P6: 义务性 | Q6: 单位和个人使用海域,必须依法取得海域使用权(直接复制原文) | S6: 【整条原文800字全部粘贴】 | T6: S07-4、S07-5 | V6: 执行性 | W6: 豆包 | X6: 张三 | AA6: 错误示范:除v0.2所列各错外,新增两错——国家层条目误填地方自主权类型、漏填央地权限配置
A7: S07-002 | B7: 中华人民共和国可再生能源法(2005年版) | C7: 主席令第二十三号 | D7: 法律 | E7: 国家 | F7: 全国人大及其常委会 | G7: 2005-02-28 | H7: 2006-01-01 | I7: 已修订 | J7: 2009-12-26 | K7: 海洋可再生能源 | L7: 价格、财税与市场机制 | M7: 第十四条 | N7: 电网企业 | O7: 可再生能源发电项目已依法取得行政许可并接入电网 | P7: 义务性 | Q7: 全额收购其电网覆盖范围内可再生能源并网发电项目的上网电量 | R7: 未履行收购义务造成损失的应当承担赔偿责任 | S7: 【核实后填入不超过200字的原文】 | T7: S07-003 | U7: 未作规定 | W7: 国家法律法规数据库 | X7: 2023001 张三 | Y7: v1 | Z7: 2026-08-20 | AA7: 边界情况:规范对象是电网企业,对地方权限沉默,故央地权限配置=未作规定——与ex1的「统一执行」对比讲解
A8: S07-003 | B8: 关于推动海洋能规模化利用的指导意见 | C8: 自然资发〔2025〕34号 | D8: 政策文件 | E8: 国家 | F8: 自然资源部 | G8: 2025-02-05 | H8: 2025-02-05 | I8: 现行有效 | K8: 海洋可再生能源 | L8: 规划与区划 | M8: 第二部分第1段 | N8: 沿海地方政府及海洋能开发企业(抽象对象) | O8: 一般情形 | P8: 指导性 | Q8: 鼓励因地制宜开展潮流能、波浪能示范工程,探索海洋能与海上风电协同开发(方向性倡导,示例表述,以核实原文为准) | R8: 本条未设 | S8: 【核实后填入不超过200字的原文】 | U8: 因地制宜 | W8: 发布机关官网 | X8: 2023001 张三 | Y8: v1 | Z8: 2026-08-20 | AA8: 指导性示范:「鼓励因地制宜」即典型的因地制宜型央地配置——指导性行为模式与因地制宜配置高频共现
A9: L45-001 | B9: 【示意】某沿海省海上风电项目竞争配置管理办法 | C9: (待核实) | D9: 地方立法 | E9: 广西 | F9: 省级主管部门 | G9: (待核实) | H9: (待核实) | I9: 现行有效 | K9: 海洋可再生能源 | L9: 价格、财税与市场机制 | M9: 第八条第二款 | N9: 省能源主管部门 | O9: 组织年度海上风电项目竞争配置 | P9: 程序性 | Q9: 将上网电价报价纳入竞争配置评分因素并设定权重(示意表述) | R9: 本条未设 | S9: 【地方层启动后核实填入】 | V9: 细化性 | W9: 发布机关官网 | X9: (地方层学生) | Y9: v1 | AA9: 地方层格式示意(内容虚构,仅示范填法):在国家竞争配置框架内细化评分规则→细化性;条目ID前缀改用L+组号
A11: 绿=满分 红=典型错误 黄=边界情况 蓝=指导性 紫=地方层示意(内容虚构,仅示范格式)。开学第一课投影前四行:先让学生找红行错误,再对比绿行与蓝行——同是「应当/鼓励」,为何一个义务性一个指导性;讲央地字段时用ex1与ex3对比「统一执行」与「未作规定」。

Sheet 修订日志
A1: 标注规范修订日志
A2: 每个坑都记在这里。这份日志是首篇文章的核心素材。
A4: 日期 | B4: 版本 | C4: 改动字段 | D4: 改动内容 | E4: 触发原因(踩了什么坑)
A5: 2026-08-08 | B5: v0.1 | C5: — | D5: 初版建立,24个字段 | E5: Day2 设计
A6: 2026-08-17 | B6: v0.2 | C6: 主题标签 | D6: 七类流程型标签重构为九类对象型标签 | E6: 收集85份规范时发现:预设流程标签限制阅读判断;实际文件按对象聚类更自然
A7: 2026-08-17 | B7: v0.2 | C7: 位阶 | D7: 「地方性法规」替换为「地方立法」 | E7: 地方层面须同时涵盖地方性法规与地方政府规章;现有数据零迁移成本
A8: 2026-08-17 | B8: v0.2 | C8: 文号 | D8: 法律可不填或写「无文号」 | E8: 多部法律无发文字号,强制必填导致占位符泛滥
A9: 2026-08-17 | B9: v0.2 | C9: 发布机关 | D9: 更名发布机关/牵头机关;词表增财政部、国土资源部(已并入自然资源部) | E9: 实际清单出现财税文件与国土资源部旧规章
A10: 2026-08-17 | B10: v0.2 | C10: 条文定位 | D10: 允许「第X段」 | E10: 大量政策文件无条款结构,原规则无法适用
A11: 2026-08-17 | B11: v0.2 | C11: 行为模式类型 | D11: 增设「指导性」 | E11: 经济公法含大量框架性规则:对象抽象、无直接执行力,功能在于指明方向、留出创造空间
A12: 2026-08-17 | B12: v0.2 | C12: 规范清单新列 | D12: 增设核心程度(1-5星,≥4星双人录入)、关联规范(单链) | E12: 质量控制前移;显性化规范间沿袭关系
A13: 2026-08-22 | B13: v0.4 | C13: 主题标签 | D13: 「电力基础设施」更名「能源基础设施」 | E13: 海洋能转化方向多元(电、氢、淡化水、油气),原标签使电缆管道类文件归属别扭;新名同时容纳电网并网与各类管线
A14: 2026-08-22 | B14: v0.4 | C14: 规范清单 | D14: 按核心程度→位阶→施行日期重排;标签与星级经教师核对定稿;关联规范转学生任务字段 | E14: 教学分配需要按重要性排列的认领清单;星级修订后双人增量400→360,总工作量1198
A15: 2026-08-22 | B15: v0.4 | C15: 容量核算 | D15: 学生人数按名单定为52 | E15: 实际选课名单到位
... A23: 2026-08-24 | B23: v0.5 | C23: 规范主体 | D23: 增补推断指引:未明示主体时依章节归属、上下文与权威资料推断并备注依据 | E23: 大量条文不直接写明规制对象,本科生普遍卡壳——推断过程本身是法律解释训练
